Workbook
Name AccActual: main!$R$519:$CO$519
Name AccPlan: main!$R$517:$CO$517
Name ActualRange: main!$R$518:$CO$518
Name AmountRange: main!$O$5:$O$514
Name PlanRange: main!$R$516:$CO$516

Sheet main
A1: Activity Data | R1: 2026 | BO1: 2027
R2: January | T2: February | X2: March | AB2: April | AF2: May | AK2: June | AO2: July | AT2: August | AX2: September | BB2: October | BG2: November | BK2: December | BO2: January | BT2: February | BX2: March | CB2: April | CG2: May | CK2: June | CO2: July
R3: W1 | S3: W2 | T3: W3 | U3: W4 | V3: W5 | W3: W6 | X3: W7 | Y3: W8 | Z3: W9 | AA3: W10 | AB3: W11 | AC3: W12 | AD3: W13 | AE3: W14 | AF3: W15 | AG3: W16 | AH3: W17 | AI3: W18 | AJ3: W19 | AK3: W20 | AL3: W21 | AM3: W22 | AN3: W23 | AO3: W24 | AP3: W25 | AQ3: W26 | AR3: W27 | AS3: W28 | AT3: W29 | AU3: W30 | AV3: W31 | AW3: W32 | AX3: W33 | AY3: W34 | AZ3: W35 | BA3: W36 | BB3: W37 | BC3: W38 | BD3: W39 | BE3: W40 | BF3: W41 | BG3: W42 | BH3: W43 | BI3: W44 | BJ3: W45 | BK3: W46 | BL3: W47 | BM3: W48 | BN3: W49 | BO3: W50 | BP3: W51 | BQ3: W52 | BR3: W53 | BS3: W54 | BT3: W55 | BU3: W56 | BV3: W57 | BW3: W58 | BX3: W59 | BY3: W60 | BZ3: W61 | CA3: W62 | CB3: W63 | CC3: W64 | CD3: W65 | CE3: W66 | CF3: W67 | CG3: W68 | CH3: W69 | CI3: W70 | CJ3: W71 | CK3: W72 | CL3: W73 | CM3: W74 | CN3: W75 | CO3: W76
A4: Row Type | B4: WBS | C4: Description | D4: P/A | E4: Activity ID | F4: Task ID | G4: UID | H4: Outline Level | I4: Plan Start | J4: Plan Finish | K4: Actual Start | L4: Actual Finish | M4: % Complete | N4: Physical % | O4: Amount | P4: Total Float (hr) | Q4: XML Amount | R4: 46045 | S4: 46052 | T4: 46059 | U4: 46066 | V4: 46073 | W4: 46080 | X4: 46087 | Y4: 46094 | Z4: 46101 | AA4: 46108 | AB4: 46115 | AC4: 46122 | AD4: 46129 | AE4: 46136 | AF4: 46143 | AG4: 46150 | AH4: 46157 | AI4: 46164 | AJ4: 46171 | AK4: 46178 | AL4: 46185 | AM4: 46192 | AN4: 46199 | AO4: 46206 | AP4: 46213 | AQ4: 46220 | AR4: 46227 | AS4: 46234 | AT4: 46241 | AU4: 46248 | AV4: 46255 | AW4: 46262 | AX4: 46269 | AY4: 46276 | AZ4: 46283 | BA4: 46290 | BB4: 46297 | BC4: 46304 | BD4: 46311 | BE4: 46318 | BF4: 46325 | BG4: 46332 | BH4: 46339 | BI4: 46346 | BJ4: 46353 | BK4: 46360 | BL4: 46367 | BM4: 46374 | BN4: 46381 | BO4: 46388 | BP4: 46395 | BQ4: 46402 | BR4: 46409 | BS4: 46416 | BT4: 46423 | BU4: 46430 | BV4: 46437 | BW4: 46444 | BX4: 46451 | BY4: 46458 | BZ4: 46465 | CA4: 46472 | CB4: 46479 | CC4: 46486 | CD4: 46493 | CE4: 46500 | CF4: 46507 | CG4: 46514 | CH4: 46521 | CI4: 46528 | CJ4: 46535 | CK4: 46542 | CL4: 46549 | CM4: 46556 | CN4: 46563 | CO4: 46570
A5: Project Summary | C5: NKC2 | D5: P | H5: 0 | I5: 46076 | J5: 46538 | M5: =IF(COUNT(R5:CO5)=0,"",SUM(R5:CO5)) -> 1 | O5: =SUMIFS($O$6:$O$513,$A$6:$A$513,"Activity",$D$6:$D$513,"P") -> 17200000 | R5: =IF(COUNTIFS($A$7:$A$514,"Activity",$D$7:$D$514,"P",R$7:R$514,"<>")=0,"",IFERROR(SUMPRODUCT(--($A$7:$A$514="Activity"),--($D$7:$D$514="P"),$O$7:$O$514,R$7:R$514)/SUMPRODUCT(--($A$7:$A$514="Activity"),--($D$7:$D$514="P"),$O$7:$O$514),"")) | S5: =IF(COUNTIFS($A$7:$A$514,"Activity",$D$7:$D$514,"P",S$7:S$514,"<>")=0,"",IFERROR(SUMPRODUCT(--($A$7:$A$514="Activity"),--($D$7:$D$514="P"),$O$7:$O$514,S$7:S$514)/SUMPRODUCT(--($A$7:$A$514="Activity"),--($D$7:$D$514="P"),$O$7:$O$514),"")) | T5: =IF(COUNTIFS($A$7:$A$514,"Activity",$D$7:$D$514,"P",T$7:T$514,"<>")=0,"",IFERROR(SUMPRODUCT(--($A$7:$A$514="Activity"),--($D$7:$D$514="P"),$O$7:$O$514,T$7:T$514)/SUMPRODUCT(--($A$7:$A$514="Activity"),--($D$7:$D$514="P"),$O$7:$O$514),"")) | U5: =IF(COUNTIFS($A$7:$A$514,"Activity",$D$7:$D$514,"P",U$7:U$514,"<>")=0,"",IFERROR(SUMPRODUCT(--($A$7:$A$514="Activity"),--($D$7:$D$514="P"),$O$7:$O$514,U$7:U$514)/SUMPRODUCT(--($A$7:$A$514="Activity"),--($D$7:$D$514="P"),$O$7:$O$514),"")) | V5: =IF(COUNTIFS($A$7:$A$514,"Activity",$D$7:$D$514,"P",V$7:V$514,"<>")=0,"",IFERROR(SUMPRODUCT(--($A$7:$A$514="Activity"),--($D$7:$D$514="P"),$O$7:$O$514,V$7:V$514)/SUMPRODUCT(--($A$7:$A$514="Activity"),--($D$7:$D$514="P"),$O$7:$O$514),"")) | W5: =IF(COUNTIFS($A$7:$A$514,"Activity",$D$7:$D$514,"P",W$7:W$514,"<>")=0,"",IFERROR(SUMPRODUCT(--($A$7:$A$514="Activity"),--($D$7:$D$514="P"),$O$7:$O$514,W$7:W$514)/SUMPRODUCT(--($A$7:$A$514="Activity"),--($D$7:$D$514="P"),$O$7:$O$514),"")) -> 0.00088090204 | X5: =IF(COUNTIFS($A$7:$A$514,"Activity",$D$7:$D$514,"P",X$7:X$514,"<>")=0,"",IFERROR(SUMPRODUCT(--($A$7:$A$514="Activity"),--($D$7:$D$514="P"),$O$7:$O$514,X$7:X$514)/SUMPRODUCT(--($A$7:$A$514="Activity"),--($D$7:$D$514="P"),$O$7:$O$514),"")) -> 0.0010962337 | Y5: =IF(COUNTIFS($A$7:$A$514,"Activity",$D$7:$D$514,"P",Y$7:Y$514,"<>")=0,"",IFERROR(SUMPRODUCT(--($A$7:$A$514="Activity"),--($D$7:$D$514="P"),$O$7:$O$514,Y$7:Y$514)/SUMPRODUCT(--($A$7:$A$514="Activity"),--($D$7:$D$514="P"),$O$7:$O$514),"")) -> 0.00095920445 | ... CO5: =IF(COUNTIFS($A$7:$A$514,"Activity",$D$7:$D$514,"P",CO$7:CO$514,"<>")=0,"",IFERROR(SUMPRODUCT(--($A$7:$A$514="Activity"),--($D$7:$D$514="P"),$O$7:$O$514,CO$7:CO$514)/SUMPRODUCT(--($A$7:$A$514="Activity"),--($D$7:$D$514="P"),$O$7:$O$514),""))
D6: A | M6: =IF(COUNT(R6:CO6)=0,"",SUM(R6:CO6)) | O6: =O5 -> 17200000 | R6: =IF(COUNTIFS($E$7:$E$514,"<>",$D$7:$D$514,"A",R$7:R$514,"<>")=0,"",IFERROR(SUMPRODUCT(--($E$7:$E$514<>""),--($D$7:$D$514="A"),$O$7:$O$514,R$7:R$514)/SUMPRODUCT(--($E$7:$E$514<>""),--($D$7:$D$514="A"),$O$7:$O$514),"")) | S6: =IF(COUNTIFS($E$7:$E$514,"<>",$D$7:$D$514,"A",S$7:S$514,"<>")=0,"",IFERROR(SUMPRODUCT(--($E$7:$E$514<>""),--($D$7:$D$514="A"),$O$7:$O$514,S$7:S$514)/SUMPRODUCT(--($E$7:$E$514<>""),--($D$7:$D$514="A"),$O$7:$O$514),"")) | T6: =IF(COUNTIFS($E$7:$E$514,"<>",$D$7:$D$514,"A",T$7:T$514,"<>")=0,"",IFERROR(SUMPRODUCT(--($E$7:$E$514<>""),--($D$7:$D$514="A"),$O$7:$O$514,T$7:T$514)/SUMPRODUCT(--($E$7:$E$514<>""),--($D$7:$D$514="A"),$O$7:$O$514),"")) | U6: =IF(COUNTIFS($E$7:$E$514,"<>",$D$7:$D$514,"A",U$7:U$514,"<>")=0,"",IFERROR(SUMPRODUCT(--($E$7:$E$514<>""),--($D$7:$D$514="A"),$O$7:$O$514,U$7:U$514)/SUMPRODUCT(--($E$7:$E$514<>""),--($D$7:$D$514="A"),$O$7:$O$514),"")) | V6: =IF(COUNTIFS($E$7:$E$514,"<>",$D$7:$D$514,"A",V$7:V$514,"<>")=0,"",IFERROR(SUMPRODUCT(--($E$7:$E$514<>""),--($D$7:$D$514="A"),$O$7:$O$514,V$7:V$514)/SUMPRODUCT(--($E$7:$E$514<>""),--($D$7:$D$514="A"),$O$7:$O$514),"")) | W6: =IF(COUNTIFS($E$7:$E$514,"<>",$D$7:$D$514,"A",W$7:W$514,"<>")=0,"",IFERROR(SUMPRODUCT(--($E$7:$E$514<>""),--($D$7:$D$514="A"),$O$7:$O$514,W$7:W$514)/SUMPRODUCT(--($E$7:$E$514<>""),--($D$7:$D$514="A"),$O$7:$O$514),"")) | X6: =IF(COUNTIFS($E$7:$E$514,"<>",$D$7:$D$514,"A",X$7:X$514,"<>")=0,"",IFERROR(SUMPRODUCT(--($E$7:$E$514<>""),--($D$7:$D$514="A"),$O$7:$O$514,X$7:X$514)/SUMPRODUCT(--($E$7:$E$514<>""),--($D$7:$D$514="A"),$O$7:$O$514),"")) | Y6: =IF(COUNTIFS($E$7:$E$514,"<>",$D$7:$D$514,"A",Y$7:Y$514,"<>")=0,"",IFERROR(SUMPRODUCT(--($E$7:$E$514<>""),--($D$7:$D$514="A"),$O$7:$O$514,Y$7:Y$514)/SUMPRODUCT(--($E$7:$E$514<>""),--($D$7:$D$514="A"),$O$7:$O$514),"")) | ... CO6: =IF(COUNTIFS($E$7:$E$514,"<>",$D$7:$D$514,"A",CO$7:CO$514,"<>")=0,"",IFERROR(SUMPRODUCT(--($E$7:$E$514<>""),--($D$7:$D$514="A"),$O$7:$O$514,CO$7:CO$514)/SUMPRODUCT(--($E$7:$E$514<>""),--($D$7:$D$514="A"),$O$7:$O$514),""))
A7: WBS | B7: 1 | C7: งานเตรียมงาน | D7: P | F7: 1 | G7: 1 | H7: 1 | I7: 46076.333 | J7: 46268.667 | M7: =IF(COUNT(R7:CO7)=0,"",SUM(R7:CO7)) -> 1 | O7: =SUMIFS($O$8:$O$35,$A$8:$A$35,"Activity",$D$8:$D$35,"P") -> 1100000 | R7: =IF(COUNTIFS($A$9:$A$36,"Activity",$D$9:$D$36,"P",R$9:R$36,"<>")=0,"",IFERROR(SUMPRODUCT(--($A$9:$A$36="Activity"),--($D$9:$D$36="P"),$O$9:$O$36,R$9:R$36)/SUMPRODUCT(--($A$9:$A$36="Activity"),--($D$9:$D$36="P"),$O$9:$O$36),"")) | S7: =IF(COUNTIFS($A$9:$A$36,"Activity",$D$9:$D$36,"P",S$9:S$36,"<>")=0,"",IFERROR(SUMPRODUCT(--($A$9:$A$36="Activity"),--($D$9:$D$36="P"),$O$9:$O$36,S$9:S$36)/SUMPRODUCT(--($A$9:$A$36="Activity"),--($D$9:$D$36="P"),$O$9:$O$36),"")) | T7: =IF(COUNTIFS($A$9:$A$36,"Activity",$D$9:$D$36,"P",T$9:T$36,"<>")=0,"",IFERROR(SUMPRODUCT(--($A$9:$A$36="Activity"),--($D$9:$D$36="P"),$O$9:$O$36,T$9:T$36)/SUMPRODUCT(--($A$9:$A$36="Activity"),--($D$9:$D$36="P"),$O$9:$O$36),"")) | U7: =IF(COUNTIFS($A$9:$A$36,"Activity",$D$9:$D$36,"P",U$9:U$36,"<>")=0,"",IFERROR(SUMPRODUCT(--($A$9:$A$36="Activity"),--($D$9:$D$36="P"),$O$9:$O$36,U$9:U$36)/SUMPRODUCT(--($A$9:$A$36="Activity"),--($D$9:$D$36="P"),$O$9:$O$36),"")) | V7: =IF(COUNTIFS($A$9:$A$36,"Activity",$D$9:$D$36,"P",V$9:V$36,"<>")=0,"",IFERROR(SUMPRODUCT(--($A$9:$A$36="Activity"),--($D$9:$D$36="P"),$O$9:$O$36,V$9:V$36)/SUMPRODUCT(--($A$9:$A$36="Activity"),--($D$9:$D$36="P"),$O$9:$O$36),"")) | W7: =IF(COUNTIFS($A$9:$A$36,"Activity",$D$9:$D$36,"P",W$9:W$36,"<>")=0,"",IFERROR(SUMPRODUCT(--($A$9:$A$36="Activity"),--($D$9:$D$36="P"),$O$9:$O$36,W$9:W$36)/SUMPRODUCT(--($A$9:$A$36="Activity"),--($D$9:$D$36="P"),$O$9:$O$36),"")) -> 0.013774105 | X7: =IF(COUNTIFS($A$9:$A$36,"Activity",$D$9:$D$36,"P",X$9:X$36,"<>")=0,"",IFERROR(SUMPRODUCT(--($A$9:$A$36="Activity"),--($D$9:$D$36="P"),$O$9:$O$36,X$9:X$36)/SUMPRODUCT(--($A$9:$A$36="Activity"),--($D$9:$D$36="P"),$O$9:$O$36),"")) -> 0.017141108 | Y7: =IF(COUNTIFS($A$9:$A$36,"Activity",$D$9:$D$36,"P",Y$9:Y$36,"<>")=0,"",IFERROR(SUMPRODUCT(--($A$9:$A$36="Activity"),--($D$9:$D$36="P"),$O$9:$O$36,Y$9:Y$36)/SUMPRODUCT(--($A$9:$A$36="Activity"),--($D$9:$D$36="P"),$O$9:$O$36),"")) -> 0.01499847 | ... CO7: =IF(COUNTIFS($A$9:$A$36,"Activity",$D$9:$D$36,"P",CO$9:CO$36,"<>")=0,"",IFERROR(SUMPRODUCT(--($A$9:$A$36="Activity"),--($D$9:$D$36="P"),$O$9:$O$36,CO$9:CO$36)/SUMPRODUCT(--($A$9:$A$36="Activity"),--($D$9:$D$36="P"),$O$9:$O$36),""))
D8: A | M8: =IF(COUNT(R8:CO8)=0,"",SUM(R8:CO8)) | O8: =O7 -> 1100000 | R8: =IF(COUNTIFS($E$9:$E$36,"<>",$D$9:$D$36,"A",R$9:R$36,"<>")=0,"",IFERROR(SUMPRODUCT(--($E$9:$E$36<>""),--($D$9:$D$36="A"),$O$9:$O$36,R$9:R$36)/SUMPRODUCT(--($E$9:$E$36<>""),--($D$9:$D$36="A"),$O$9:$O$36),"")) | S8: =IF(COUNTIFS($E$9:$E$36,"<>",$D$9:$D$36,"A",S$9:S$36,"<>")=0,"",IFERROR(SUMPRODUCT(--($E$9:$E$36<>""),--($D$9:$D$36="A"),$O$9:$O$36,S$9:S$36)/SUMPRODUCT(--($E$9:$E$36<>""),--($D$9:$D$36="A"),$O$9:$O$36),"")) | T8: =IF(COUNTIFS($E$9:$E$36,"<>",$D$9:$D$36,"A",T$9:T$36,"<>")=0,"",IFERROR(SUMPRODUCT(--($E$9:$E$36<>""),--($D$9:$D$36="A"),$O$9:$O$36,T$9:T$36)/SUMPRODUCT(--($E$9:$E$36<>""),--($D$9:$D$36="A"),$O$9:$O$36),"")) | U8: =IF(COUNTIFS($E$9:$E$36,"<>",$D$9:$D$36,"A",U$9:U$36,"<>")=0,"",IFERROR(SUMPRODUCT(--($E$9:$E$36<>""),--($D$9:$D$36="A"),$O$9:$O$36,U$9:U$36)/SUMPRODUCT(--($E$9:$E$36<>""),--($D$9:$D$36="A"),$O$9:$O$36),"")) | V8: =IF(COUNTIFS($E$9:$E$36,"<>",$D$9:$D$36,"A",V$9:V$36,"<>")=0,"",IFERROR(SUMPRODUCT(--($E$9:$E$36<>""),--($D$9:$D$36="A"),$O$9:$O$36,V$9:V$36)/SUMPRODUCT(--($E$9:$E$36<>""),--($D$9:$D$36="A"),$O$9:$O$36),"")) | W8: =IF(COUNTIFS($E$9:$E$36,"<>",$D$9:$D$36,"A",W$9:W$36,"<>")=0,"",IFERROR(SUMPRODUCT(--($E$9:$E$36<>""),--($D$9:$D$36="A"),$O$9:$O$36,W$9:W$36)/SUMPRODUCT(--($E$9:$E$36<>""),--($D$9:$D$36="A"),$O$9:$O$36),"")) | X8: =IF(COUNTIFS($E$9:$E$36,"<>",$D$9:$D$36,"A",X$9:X$36,"<>")=0,"",IFERROR(SUMPRODUCT(--($E$9:$E$36<>""),--($D$9:$D$36="A"),$O$9:$O$36,X$9:X$36)/SUMPRODUCT(--($E$9:$E$36<>""),--($D$9:$D$36="A"),$O$9:$O$36),"")) | Y8: =IF(COUNTIFS($E$9:$E$36,"<>",$D$9:$D$36,"A",Y$9:Y$36,"<>")=0,"",IFERROR(SUMPRODUCT(--($E$9:$E$36<>""),--($D$9:$D$36="A"),$O$9:$O$36,Y$9:Y$36)/SUMPRODUCT(--($E$9:$E$36<>""),--($D$9:$D$36="A"),$O$9:$O$36),"")) | ... CO8: =IF(COUNTIFS($E$9:$E$36,"<>",$D$9:$D$36,"A",CO$9:CO$36,"<>")=0,"",IFERROR(SUMPRODUCT(--($E$9:$E$36<>""),--($D$9:$D$36="A"),$O$9:$O$36,CO$9:CO$36)/SUMPRODUCT(--($E$9:$E$36<>""),--($D$9:$D$36="A"),$O$9:$O$36),""))
A9: WBS | B9: 1.1 | C9: Mobilization | D9: P | F9: 2 | G9: 2 | H9: 2 | I9: 46076.333 | J9: 46136.667 | M9: =IF(COUNT(R9:CO9)=0,"",SUM(R9:CO9)) -> 1 | O9: =SUMIFS($O$10:$O$11,$A$10:$A$11,"Activity",$D$10:$D$11,"P") -> 100000 | R9: =IF(COUNTIFS($A$11:$A$12,"Activity",$D$11:$D$12,"P",R$11:R$12,"<>")=0,"",IFERROR(SUMPRODUCT(--($A$11:$A$12="Activity"),--($D$11:$D$12="P"),$O$11:$O$12,R$11:R$12)/SUMPRODUCT(--($A$11:$A$12="Activity"),--($D$11:$D$12="P"),$O$11:$O$12),"")) | S9: =IF(COUNTIFS($A$11:$A$12,"Activity",$D$11:$D$12,"P",S$11:S$12,"<>")=0,"",IFERROR(SUMPRODUCT(--($A$11:$A$12="Activity"),--($D$11:$D$12="P"),$O$11:$O$12,S$11:S$12)/SUMPRODUCT(--($A$11:$A$12="Activity"),--($D$11:$D$12="P"),$O$11:$O$12),"")) | T9: =IF(COUNTIFS($A$11:$A$12,"Activity",$D$11:$D$12,"P",T$11:T$12,"<>")=0,"",IFERROR(SUMPRODUCT(--($A$11:$A$12="Activity"),--($D$11:$D$12="P"),$O$11:$O$12,T$11:T$12)/SUMPRODUCT(--($A$11:$A$12="Activity"),--($D$11:$D$12="P"),$O$11:$O$12),"")) | U9: =IF(COUNTIFS($A$11:$A$12,"Activity",$D$11:$D$12,"P",U$11:U$12,"<>")=0,"",IFERROR(SUMPRODUCT(--($A$11:$A$12="Activity"),--($D$11:$D$12="P"),$O$11:$O$12,U$11:U$12)/SUMPRODUCT(--($A$11:$A$12="Activity"),--($D$11:$D$12="P"),$O$11:$O$12),"")) | V9: =IF(COUNTIFS($A$11:$A$12,"Activity",$D$11:$D$12,"P",V$11:V$12,"<>")=0,"",IFERROR(SUMPRODUCT(--($A$11:$A$12="Activity"),--($D$11:$D$12="P"),$O$11:$O$12,V$11:V$12)/SUMPRODUCT(--($A$11:$A$12="Activity"),--($D$11:$D$12="P"),$O$11:$O$12),"")) | W9: =IF(COUNTIFS($A$11:$A$12,"Activity",$D$11:$D$12,"P",W$11:W$12,"<>")=0,"",IFERROR(SUMPRODUCT(--($A$11:$A$12="Activity"),--($D$11:$D$12="P"),$O$11:$O$12,W$11:W$12)/SUMPRODUCT(--($A$11:$A$12="Activity"),--($D$11:$D$12="P"),$O$11:$O$12),"")) -> 0.15151515 | X9: =IF(COUNTIFS($A$11:$A$12,"Activity",$D$11:$D$12,"P",X$11:X$12,"<>")=0,"",IFERROR(SUMPRODUCT(--($A$11:$A$12="Activity"),--($D$11:$D$12="P"),$O$11:$O$12,X$11:X$12)/SUMPRODUCT(--($A$11:$A$12="Activity"),--($D$11:$D$12="P"),$O$11:$O$12),"")) -> 0.18855219 | Y9: =IF(COUNTIFS($A$11:$A$12,"Activity",$D$11:$D$12,"P",Y$11:Y$12,"<>")=0,"",IFERROR(SUMPRODUCT(--($A$11:$A$12="Activity"),--($D$11:$D$12="P"),$O$11:$O$12,Y$11:Y$12)/SUMPRODUCT(--($A$11:$A$12="Activity"),--($D$11:$D$12="P"),$O$11:$O$12),"")) -> 0.16498316 | ... CO9: =IF(COUNTIFS($A$11:$A$12,"Activity",$D$11:$D$12,"P",CO$11:CO$12,"<>")=0,"",IFERROR(SUMPRODUCT(--($A$11:$A$12="Activity"),--($D$11:$D$12="P"),$O$11:$O$12,CO$11:CO$12)/SUMPRODUCT(--($A$11:$A$12="Activity"),--($D$11:$D$12="P"),$O$11:$O$12),""))
D10: A | M10: =IF(COUNT(R10:CO10)=0,"",SUM(R10:CO10)) | O10: =O9 -> 100000 | R10: =IF(COUNTIFS($E$11:$E$12,"<>",$D$11:$D$12,"A",R$11:R$12,"<>")=0,"",IFERROR(SUMPRODUCT(--($E$11:$E$12<>""),--($D$11:$D$12="A"),$O$11:$O$12,R$11:R$12)/SUMPRODUCT(--($E$11:$E$12<>""),--($D$11:$D$12="A"),$O$11:$O$12),"")) | S10: =IF(COUNTIFS($E$11:$E$12,"<>",$D$11:$D$12,"A",S$11:S$12,"<>")=0,"",IFERROR(SUMPRODUCT(--($E$11:$E$12<>""),--($D$11:$D$12="A"),$O$11:$O$12,S$11:S$12)/SUMPRODUCT(--($E$11:$E$12<>""),--($D$11:$D$12="A"),$O$11:$O$12),"")) | T10: =IF(COUNTIFS($E$11:$E$12,"<>",$D$11:$D$12,"A",T$11:T$12,"<>")=0,"",IFERROR(SUMPRODUCT(--($E$11:$E$12<>""),--($D$11:$D$12="A"),$O$11:$O$12,T$11:T$12)/SUMPRODUCT(--($E$11:$E$12<>""),--($D$11:$D$12="A"),$O$11:$O$12),"")) | U10: =IF(COUNTIFS($E$11:$E$12,"<>",$D$11:$D$12,"A",U$11:U$12,"<>")=0,"",IFERROR(SUMPRODUCT(--($E$11:$E$12<>""),--($D$11:$D$12="A"),$O$11:$O$12,U$11:U$12)/SUMPRODUCT(--($E$11:$E$12<>""),--($D$11:$D$12="A"),$O$11:$O$12),"")) | V10: =IF(COUNTIFS($E$11:$E$12,"<>",$D$11:$D$12,"A",V$11:V$12,"<>")=0,"",IFERROR(SUMPRODUCT(--($E$11:$E$12<>""),--($D$11:$D$12="A"),$O$11:$O$12,V$11:V$12)/SUMPRODUCT(--($E$11:$E$12<>""),--($D$11:$D$12="A"),$O$11:$O$12),"")) | W10: =IF(COUNTIFS($E$11:$E$12,"<>",$D$11:$D$12,"A",W$11:W$12,"<>")=0,"",IFERROR(SUMPRODUCT(--($E$11:$E$12<>""),--($D$11:$D$12="A"),$O$11:$O$12,W$11:W$12)/SUMPRODUCT(--($E$11:$E$12<>""),--($D$11:$D$12="A"),$O$11:$O$12),"")) | X10: =IF(COUNTIFS($E$11:$E$12,"<>",$D$11:$D$12,"A",X$11:X$12,"<>")=0,"",IFERROR(SUMPRODUCT(--($E$11:$E$12<>""),--($D$11:$D$12="A"),$O$11:$O$12,X$11:X$12)/SUMPRODUCT(--($E$11:$E$12<>""),--($D$11:$D$12="A"),$O$11:$O$12),"")) | Y10: =IF(COUNTIFS($E$11:$E$12,"<>",$D$11:$D$12,"A",Y$11:Y$12,"<>")=0,"",IFERROR(SUMPRODUCT(--($E$11:$E$12<>""),--($D$11:$D$12="A"),$O$11:$O$12,Y$11:Y$12)/SUMPRODUCT(--($E$11:$E$12<>""),--($D$11:$D$12="A"),$O$11:$O$12),"")) | ... CO10: =IF(COUNTIFS($E$11:$E$12,"<>",$D$11:$D$12,"A",CO$11:CO$12,"<>")=0,"",IFERROR(SUMPRODUCT(--($E$11:$E$12<>""),--($D$11:$D$12="A"),$O$11:$O$12,CO$11:CO$12)/SUMPRODUCT(--($E$11:$E$12<>""),--($D$11:$D$12="A"),$O$11:$O$12),""))
A11: Activity | B11: 1.1.1 | C11: Site Mobilization | D11: P | E11: A1000 | F11: 3 | G11: 3 | H11: 3 | I11: 46076.333 | J11: 46136.667 | M11: =IF(COUNT(R11:CO11)=0,"",SUM(R11:CO11)) -> 1 | O11: 100000 | W11: 0.15151515 | X11: 0.18855219 | Y11: 0.16498316 | Z11: 0.14141414 | AA11: 0.11784512 | AB11: 0.094276094 | AC11: 0.070707071 | AD11: 0.047138047 | AE11: 0.023569024
D12: A | E12: A1000 | M12: =IF(COUNT(R12:CO12)=0,"",SUM(R12:CO12)) | N12: 0 | O12: =O11 -> 100000
A13: WBS | B13: 1.2 | C13: งานรื้อถอน | D13: P | F13: 4 | G13: 4 | H13: 2 | I13: 46129.333 | J13: 46247.667 | M13: =IF(COUNT(R13:CO13)=0,"",SUM(R13:CO13)) -> 1 | O13: =SUMIFS($O$14:$O$25,$A$14:$A$25,"Activity",$D$14:$D$25,"P") -> 600000 | R13: =IF(COUNTIFS($A$15:$A$26,"Activity",$D$15:$D$26,"P",R$15:R$26,"<>")=0,"",IFERROR(SUMPRODUCT(--($A$15:$A$26="Activity"),--($D$15:$D$26="P"),$O$15:$O$26,R$15:R$26)/SUMPRODUCT(--($A$15:$A$26="Activity"),--($D$15:$D$26="P"),$O$15:$O$26),"")) | S13: =IF(COUNTIFS($A$15:$A$26,"Activity",$D$15:$D$26,"P",S$15:S$26,"<>")=0,"",IFERROR(SUMPRODUCT(--($A$15:$A$26="Activity"),--($D$15:$D$26="P"),$O$15:$O$26,S$15:S$26)/SUMPRODUCT(--($A$15:$A$26="Activity"),--($D$15:$D$26="P"),$O$15:$O$26),"")) | T13: =IF(COUNTIFS($A$15:$A$26,"Activity",$D$15:$D$26,"P",T$15:T$26,"<>")=0,"",IFERROR(SUMPRODUCT(--($A$15:$A$26="Activity"),--($D$15:$D$26="P"),$O$15:$O$26,T$15:T$26)/SUMPRODUCT(--($A$15:$A$26="Activity"),--($D$15:$D$26="P"),$O$15:$O$26),"")) | U13: =IF(COUNTIFS($A$15:$A$26,"Activity",$D$15:$D$26,"P",U$15:U$26,"<>")=0,"",IFERROR(SUMPRODUCT(--($A$15:$A$26="Activity"),--($D$15:$D$26="P"),$O$15:$O$26,U$15:U$26)/SUMPRODUCT(--($A$15:$A$26="Activity"),--($D$15:$D$26="P"),$O$15:$O$26),"")) | V13: =IF(COUNTIFS($A$15:$A$26,"Activity",$D$15:$D$26,"P",V$15:V$26,"<>")=0,"",IFERROR(SUMPRODUCT(--($A$15:$A$26="Activity"),--($D$15:$D$26="P"),$O$15:$O$26,V$15:V$26)/SUMPRODUCT(--($A$15:$A$26="Activity"),--($D$15:$D$26="P"),$O$15:$O$26),"")) | W13: =IF(COUNTIFS($A$15:$A$26,"Activity",$D$15:$D$26,"P",W$15:W$26,"<>")=0,"",IFERROR(SUMPRODUCT(--($A$15:$A$26="Activity"),--($D$15:$D$26="P"),$O$15:$O$26,W$15:W$26)/SUMPRODUCT(--($A$15:$A$26="Activity"),--($D$15:$D$26="P"),$O$15:$O$26),"")) | X13: =IF(COUNTIFS($A$15:$A$26,"Activity",$D$15:$D$26,"P",X$15:X$26,"<>")=0,"",IFERROR(SUMPRODUCT(--($A$15:$A$26="Activity"),--($D$15:$D$26="P"),$O$15:$O$26,X$15:X$26)/SUMPRODUCT(--($A$15:$A$26="Activity"),--($D$15:$D$26="P"),$O$15:$O$26),"")) | Y13: =IF(COUNTIFS($A$15:$A$26,"Activity",$D$15:$D$26,"P",Y$15:Y$26,"<>")=0,"",IFERROR(SUMPRODUCT(--($A$15:$A$26="Activity"),--($D$15:$D$26="P"),$O$15:$O$26,Y$15:Y$26)/SUMPRODUCT(--($A$15:$A$26="Activity"),--($D$15:$D$26="P"),$O$15:$O$26),"")) | ... CO13: =IF(COUNTIFS($A$15:$A$26,"Activity",$D$15:$D$26,"P",CO$15:CO$26,"<>")=0,"",IFERROR(SUMPRODUCT(--($A$15:$A$26="Activity"),--($D$15:$D$26="P"),$O$15:$O$26,CO$15:CO$26)/SUMPRODUCT(--($A$15:$A$26="Activity"),--($D$15:$D$26="P"),$O$15:$O$26),""))
D14: A | M14: =IF(COUNT(R14:CO14)=0,"",SUM(R14:CO14)) | O14: =O13 -> 600000 | R14: =IF(COUNTIFS($E$15:$E$26,"<>",$D$15:$D$26,"A",R$15:R$26,"<>")=0,"",IFERROR(SUMPRODUCT(--($E$15:$E$26<>""),--($D$15:$D$26="A"),$O$15:$O$26,R$15:R$26)/SUMPRODUCT(--($E$15:$E$26<>""),--($D$15:$D$26="A"),$O$15:$O$26),"")) | S14: =IF(COUNTIFS($E$15:$E$26,"<>",$D$15:$D$26,"A",S$15:S$26,"<>")=0,"",IFERROR(SUMPRODUCT(--($E$15:$E$26<>""),--($D$15:$D$26="A"),$O$15:$O$26,S$15:S$26)/SUMPRODUCT(--($E$15:$E$26<>""),--($D$15:$D$26="A"),$O$15:$O$26),"")) | T14: =IF(COUNTIFS($E$15:$E$26,"<>",$D$15:$D$26,"A",T$15:T$26,"<>")=0,"",IFERROR(SUMPRODUCT(--($E$15:$E$26<>""),--($D$15:$D$26="A"),$O$15:$O$26,T$15:T$26)/SUMPRODUCT(--($E$15:$E$26<>""),--($D$15:$D$26="A"),$O$15:$O$26),"")) | U14: =IF(COUNTIFS($E$15:$E$26,"<>",$D$15:$D$26,"A",U$15:U$26,"<>")=0,"",IFERROR(SUMPRODUCT(--($E$15:$E$26<>""),--($D$15:$D$26="A"),$O$15:$O$26,U$15:U$26)/SUMPRODUCT(--($E$15:$E$26<>""),--($D$15:$D$26="A"),$O$15:$O$26),"")) | V14: =IF(COUNTIFS($E$15:$E$26,"<>",$D$15:$D$26,"A",V$15:V$26,"<>")=0,"",IFERROR(SUMPRODUCT(--($E$15:$E$26<>""),--($D$15:$D$26="A"),$O$15:$O$26,V$15:V$26)/SUMPRODUCT(--($E$15:$E$26<>""),--($D$15:$D$26="A"),$O$15:$O$26),"")) | W14: =IF(COUNTIFS($E$15:$E$26,"<>",$D$15:$D$26,"A",W$15:W$26,"<>")=0,"",IFERROR(SUMPRODUCT(--($E$15:$E$26<>""),--($D$15:$D$26="A"),$O$15:$O$26,W$15:W$26)/SUMPRODUCT(--($E$15:$E$26<>""),--($D$15:$D$26="A"),$O$15:$O$26),"")) | X14: =IF(COUNTIFS($E$15:$E$26,"<>",$D$15:$D$26,"A",X$15:X$26,"<>")=0,"",IFERROR(SUMPRODUCT(--($E$15:$E$26<>""),--($D$15:$D$26="A"),$O$15:$O$26,X$15:X$26)/SUMPRODUCT(--($E$15:$E$26<>""),--($D$15:$D$26="A"),$O$15:$O$26),"")) | Y14: =IF(COUNTIFS($E$15:$E$26,"<>",$D$15:$D$26,"A",Y$15:Y$26,"<>")=0,"",IFERROR(SUMPRODUCT(--($E$15:$E$26<>""),--($D$15:$D$26="A"),$O$15:$O$26,Y$15:Y$26)/SUMPRODUCT(--($E$15:$E$26<>""),--($D$15:$D$26="A"),$O$15:$O$26),"")) | ... CO14: =IF(COUNTIFS($E$15:$E$26,"<>",$D$15:$D$26,"A",CO$15:CO$26,"<>")=0,"",IFERROR(SUMPRODUCT(--($E$15:$E$26<>""),--($D$15:$D$26="A"),$O$15:$O$26,CO$15:CO$26)/SUMPRODUCT(--($E$15:$E$26<>""),--($D$15:$D$26="A"),$O$15:$O$26),""))
A15: Activity | B15: 1.2.1 | C15: Roof & Roof Floor | D15: P | E15: A1005 | F15: 5 | G15: 5 | H15: 3 | I15: 46150.333 | J15: 46170.667 | M15: =IF(COUNT(R15:CO15)=0,"",SUM(R15:CO15)) -> 1 | O15: 100000 | P15: 34.933333 | AG15: 0.047619048 | AH15: 0.33333333 | AI15: 0.33333333 | AJ15: 0.28571429
D16: A | E16: A1005 | M16: =IF(COUNT(R16:CO16)=0,"",SUM(R16:CO16)) | N16: 0 | O16: =O15 -> 100000
A17: Activity | B17: 1.2.2 | C17: 3rd Floor | D17: P | E17: A1010 | F17: 6 | G17: 6 | H17: 3 | I17: 46129.333 | J17: 46149.667 | M17: =IF(COUNT(R17:CO17)=0,"",SUM(R17:CO17)) -> 1 | O17: 100000 | P17: 0 | AD17: 0.047619048 | AE17: 0.33333333 | AF17: 0.33333333 | AG17: 0.28571429
D18: A | E18: A1010 | M18: =IF(COUNT(R18:CO18)=0,"",SUM(R18:CO18)) | N18: 0 | O18: =O17 -> 100000
A19: Activity | B19: 1.2.3 | C19: 2nd Floor | D19: P | E19: A1020 | F19: 7 | G19: 7 | H19: 3 | I19: 46150.333 | J19: 46170.667 | M19: =IF(COUNT(R19:CO19)=0,"",SUM(R19:CO19)) -> 1 | O19: 100000 | P19: 0 | AG19: 0.047619048 | AH19: 0.33333333 | AI19: 0.33333333 | AJ19: 0.28571429
D20: A | E20: A1020 | M20: =IF(COUNT(R20:CO20)=0,"",SUM(R20:CO20)) | N20: 0 | O20: =O19 -> 100000
A21: Activity | B21: 1.2.4 | C21: Mezzanine Floor | D21: P | E21: A1030 | F21: 8 | G21: 8 | H21: 3 | I21: 46171.333 | J21: 46191.667 | M21: =IF(COUNT(R21:CO21)=0,"",SUM(R21:CO21)) -> 1 | O21: 100000 | P21: 0 | AJ21: 0.047619048 | AK21: 0.33333333 | AL21: 0.33333333 | AM21: 0.28571429
D22: A | E22: A1030 | M22: =IF(COUNT(R22:CO22)=0,"",SUM(R22:CO22)) | N22: 0 | O22: =O21 -> 100000
A23: Activity | B23: 1.2.5 | C23: Ground Floor | D23: P | E23: A1040 | F23: 9 | G23: 9 | H23: 3 | I23: 46192.333 | J23: 46219.667 | M23: =IF(COUNT(R23:CO23)=0,"",SUM(R23:CO23)) -> 1 | O23: 100000 | P23: 0 | AM23: 0.035714286 | AN23: 0.25 | AO23: 0.25 | AP23: 0.25 | AQ23: 0.21428571
D24: A | E24: A1040 | M24: =IF(COUNT(R24:CO24)=0,"",SUM(R24:CO24)) | N24: 0 | O24: =O23 -> 100000
A25: Activity | B25: 1.2.6 | C25: External | D25: P | E25: A1050 | F25: 10 | G25: 10 | H25: 3 | I25: 46220.333 | J25: 46247.667 | M25: =IF(COUNT(R25:CO25)=0,"",SUM(R25:CO25)) -> 1 | O25: 100000 | P25: 27.6 | AQ25: 0.035714286 | AR25: 0.25 | AS25: 0.25 | AT25: 0.25 | AU25: 0.21428571
D26: A | E26: A1050 | M26: =IF(COUNT(R26:CO26)=0,"",SUM(R26:CO26)) | N26: 0 | O26: =O25 -> 100000
A27: WBS | B27: 1.3 | C27: งานซ่อมโครงสร้าง | D27: P | F27: 11 | G27: 11 | H27: 2 | I27: 46220.333 | J27: 46268.667 | M27: =IF(COUNT(R27:CO27)=0,"",SUM(R27:CO27)) -> 1 | O27: =SUMIFS($O$28:$O$35,$A$28:$A$35,"Activity",$D$28:$D$35,"P") -> 400000 | R27: =IF(COUNTIFS($A$29:$A$36,"Activity",$D$29:$D$36,"P",R$29:R$36,"<>")=0,"",IFERROR(SUMPRODUCT(--($A$29:$A$36="Activity"),--($D$29:$D$36="P"),$O$29:$O$36,R$29:R$36)/SUMPRODUCT(--($A$29:$A$36="Activity"),--($D$29:$D$36="P"),$O$29:$O$36),"")) | S27: =IF(COUNTIFS($A$29:$A$36,"Activity",$D$29:$D$36,"P",S$29:S$36,"<>")=0,"",IFERROR(SUMPRODUCT(--($A$29:$A$36="Activity"),--($D$29:$D$36="P"),$O$29:$O$36,S$29:S$36)/SUMPRODUCT(--($A$29:$A$36="Activity"),--($D$29:$D$36="P"),$O$29:$O$36),"")) | T27: =IF(COUNTIFS($A$29:$A$36,"Activity",$D$29:$D$36,"P",T$29:T$36,"<>")=0,"",IFERROR(SUMPRODUCT(--($A$29:$A$36="Activity"),--($D$29:$D$36="P"),$O$29:$O$36,T$29:T$36)/SUMPRODUCT(--($A$29:$A$36="Activity"),--($D$29:$D$36="P"),$O$29:$O$36),"")) | U27: =IF(COUNTIFS($A$29:$A$36,"Activity",$D$29:$D$36,"P",U$29:U$36,"<>")=0,"",IFERROR(SUMPRODUCT(--($A$29:$A$36="Activity"),--($D$29:$D$36="P"),$O$29:$O$36,U$29:U$36)/SUMPRODUCT(--($A$29:$A$36="Activity"),--($D$29:$D$36="P"),$O$29:$O$36),"")) | V27: =IF(COUNTIFS($A$29:$A$36,"Activity",$D$29:$D$36,"P",V$29:V$36,"<>")=0,"",IFERROR(SUMPRODUCT(--($A$29:$A$36="Activity"),--($D$29:$D$36="P"),$O$29:$O$36,V$29:V$36)/SUMPRODUCT(--($A$29:$A$36="Activity"),--($D$29:$D$36="P"),$O$29:$O$36),"")) | W27: =IF(COUNTIFS($A$29:$A$36,"Activity",$D$29:$D$36,"P",W$29:W$36,"<>")=0,"",IFERROR(SUMPRODUCT(--($A$29:$A$36="Activity"),--($D$29:$D$36="P"),$O$29:$O$36,W$29:W$36)/SUMPRODUCT(--($A$29:$A$36="Activity"),--($D$29:$D$36="P"),$O$29:$O$36),"")) | X27: =IF(COUNTIFS($A$29:$A$36,"Activity",$D$29:$D$36,"P",X$29:X$36,"<>")=0,"",IFERROR(SUMPRODUCT(--($A$29:$A$36="Activity"),--($D$29:$D$36="P"),$O$29:$O$36,X$29:X$36)/SUMPRODUCT(--($A$29:$A$36="Activity"),--($D$29:$D$36="P"),$O$29:$O$36),"")) | Y27: =IF(COUNTIFS($A$29:$A$36,"Activity",$D$29:$D$36,"P",Y$29:Y$36,"<>")=0,"",IFERROR(SUMPRODUCT(--($A$29:$A$36="Activity"),--($D$29:$D$36="P"),$O$29:$O$36,Y$29:Y$36)/SUMPRODUCT(--($A$29:$A$36="Activity"),--($D$29:$D$36="P"),$O$29:$O$36),"")) | ... CO27: =IF(COUNTIFS($A$29:$A$36,"Activity",$D$29:$D$36,"P",CO$29:CO$36,"<>")=0,"",IFERROR(SUMPRODUCT(--($A$29:$A$36="Activity"),--($D$29:$D$36="P"),$O$29:$O$36,CO$29:CO$36)/SUMPRODUCT(--($A$29:$A$36="Activity"),--($D$29:$D$36="P"),$O$29:$O$36),""))
D28: A | M28: =IF(COUNT(R28:CO28)=0,"",SUM(R28:CO28)) | O28: =O27 -> 400000 | R28: =IF(COUNTIFS($E$29:$E$36,"<>",$D$29:$D$36,"A",R$29:R$36,"<>")=0,"",IFERROR(SUMPRODUCT(--($E$29:$E$36<>""),--($D$29:$D$36="A"),$O$29:$O$36,R$29:R$36)/SUMPRODUCT(--($E$29:$E$36<>""),--($D$29:$D$36="A"),$O$29:$O$36),"")) | S28: =IF(COUNTIFS($E$29:$E$36,"<>",$D$29:$D$36,"A",S$29:S$36,"<>")=0,"",IFERROR(SUMPRODUCT(--($E$29:$E$36<>""),--($D$29:$D$36="A"),$O$29:$O$36,S$29:S$36)/SUMPRODUCT(--($E$29:$E$36<>""),--($D$29:$D$36="A"),$O$29:$O$36),"")) | T28: =IF(COUNTIFS($E$29:$E$36,"<>",$D$29:$D$36,"A",T$29:T$36,"<>")=0,"",IFERROR(SUMPRODUCT(--($E$29:$E$36<>""),--($D$29:$D$36="A"),$O$29:$O$36,T$29:T$36)/SUMPRODUCT(--($E$29:$E$36<>""),--($D$29:$D$36="A"),$O$29:$O$36),"")) | U28: =IF(COUNTIFS($E$29:$E$36,"<>",$D$29:$D$36,"A",U$29:U$36,"<>")=0,"",IFERROR(SUMPRODUCT(--($E$29:$E$36<>""),--($D$29:$D$36="A"),$O$29:$O$36,U$29:U$36)/SUMPRODUCT(--($E$29:$E$36<>""),--($D$29:$D$36="A"),$O$29:$O$36),"")) | V28: =IF(COUNTIFS($E$29:$E$36,"<>",$D$29:$D$36,"A",V$29:V$36,"<>")=0,"",IFERROR(SUMPRODUCT(--($E$29:$E$36<>""),--($D$29:$D$36="A"),$O$29:$O$36,V$29:V$36)/SUMPRODUCT(--($E$29:$E$36<>""),--($D$29:$D$36="A"),$O$29:$O$36),"")) | W28: =IF(COUNTIFS($E$29:$E$36,"<>",$D$29:$D$36,"A",W$29:W$36,"<>")=0,"",IFERROR(SUMPRODUCT(--($E$29:$E$36<>""),--($D$29:$D$36="A"),$O$29:$O$36,W$29:W$36)/SUMPRODUCT(--($E$29:$E$36<>""),--($D$29:$D$36="A"),$O$29:$O$36),"")) | X28: =IF(COUNTIFS($E$29:$E$36,"<>",$D$29:$D$36,"A",X$29:X$36,"<>")=0,"",IFERROR(SUMPRODUCT(--($E$29:$E$36<>""),--($D$29:$D$36="A"),$O$29:$O$36,X$29:X$36)/SUMPRODUCT(--($E$29:$E$36<>""),--($D$29:$D$36="A"),$O$29:$O$36),"")) | Y28: =IF(COUNTIFS($E$29:$E$36,"<>",$D$29:$D$36,"A",Y$29:Y$36,"<>")=0,"",IFERROR(SUMPRODUCT(--($E$29:$E$36<>""),--($D$29:$D$36="A"),$O$29:$O$36,Y$29:Y$36)/SUMPRODUCT(--($E$29:$E$36<>""),--($D$29:$D$36="A"),$O$29:$O$36),"")) | ... CO28: =IF(COUNTIFS($E$29:$E$36,"<>",$D$29:$D$36,"A",CO$29:CO$36,"<>")=0,"",IFERROR(SUMPRODUCT(--($E$29:$E$36<>""),--($D$29:$D$36="A"),$O$29:$O$36,CO$29:CO$36)/SUMPRODUCT(--($E$29:$E$36<>""),--($D$29:$D$36="A"),$O$29:$O$36),""))
A29: Activity | B29: 1.3.1 | C29: Ground FL | D29: P | E29: A1060 | F29: 12 | G29: 12 | H29: 3 | I29: 46220.333 | J29: 46233.667 | M29: =IF(COUNT(R29:CO29)=0,"",SUM(R29:CO29)) -> 1 | O29: 100000 | P29: 0 | AQ29: 0.071428571 | AR29: 0.5 | AS29: 0.42857143
D30: A | E30: A1060 | M30: =IF(COUNT(R30:CO30)=0,"",SUM(R30:CO30)) | N30: 0 | O30: =O29 -> 100000
A31: Activity | B31: 1.3.2 | C31: 2nd FL | D31: P | E31: A1070 | F31: 13 | G31: 13 | H31: 3 | I31: 46234.333 | J31: 46247.667 | M31: =IF(COUNT(R31:CO31)=0,"",SUM(R31:CO31)) -> 1 | O31: 100000 | P31: 0 | AS31: 0.071428571 | AT31: 0.5 | AU31: 0.42857143
D32: A | E32: A1070 | M32: =IF(COUNT(R32:CO32)=0,"",SUM(R32:CO32)) | N32: 0 | O32: =O31 -> 100000
A33: Activity | B33: 1.3.3 | C33: 3rd FL | D33: P | E33: A1080 | F33: 14 | G33: 14 | H33: 3 | I33: 46248.333 | J33: 46261.667 | M33: =IF(COUNT(R33:CO33)=0,"",SUM(R33:CO33)) -> 1 | O33: 100000 | P33: 0 | AU33: 0.071428571 | AV33: 0.5 | AW33: 0.42857143
D34: A | E34: A1080 | M34: =IF(COUNT(R34:CO34)=0,"",SUM(R34:CO34)) | N34: 0 | O34: =O33 -> 100000
A35: Activity | B35: 1.3.4 | C35: Roof FL | D35: P | E35: A1090 | F35: 15 | G35: 15 | H35: 3 | I35: 46262.333 | J35: 46268.667 | M35: =IF(COUNT(R35:CO35)=0,"",SUM(R35:CO35)) -> 1 | O35: 100000 | P35: 0 | AW35: 0.14285714 | AX35: 0.85714286
D36: A | E36: A1090 | M36: =IF(COUNT(R36:CO36)=0,"",SUM(R36:CO36)) | N36: 0 | O36: =O35 -> 100000
A37: WBS | B37: 2 | C37: Structure | D37: P | F37: 16 | G37: 16 | H37: 1 | I37: 46230.333 | J37: 46435.667 | M37: =IF(COUNT(R37:CO37)=0,"",SUM(R37:CO37)) -> 1 | O37: =SUMIFS($O$38:$O$147,$A$38:$A$147,"Activity",$D$38:$D$147,"P") -> 4300000 | R37: =IF(COUNTIFS($A$39:$A$148,"Activity",$D$39:$D$148,"P",R$39:R$148,"<>")=0,"",IFERROR(SUMPRODUCT(--($A$39:$A$148="Activity"),--($D$39:$D$148="P"),$O$39:$O$148,R$39:R$148)/SUMPRODUCT(--($A$39:$A$148="Activity"),--($D$39:$D$148="P"),$O$39:$O$148),"")) | S37: =IF(COUNTIFS($A$39:$A$148,"Activity",$D$39:$D$148,"P",S$39:S$148,"<>")=0,"",IFERROR(SUMPRODUCT(--($A$39:$A$148="Activity"),--($D$39:$D$148="P"),$O$39:$O$148,S$39:S$148)/SUMPRODUCT(--($A$39:$A$148="Activity"),--($D$39:$D$148="P"),$O$39:$O$148),"")) | T37: =IF(COUNTIFS($A$39:$A$148,"Activity",$D$39:$D$148,"P",T$39:T$148,"<>")=0,"",IFERROR(SUMPRODUCT(--($A$39:$A$148="Activity"),--($D$39:$D$148="P"),$O$39:$O$148,T$39:T$148)/SUMPRODUCT(--($A$39:$A$148="Activity"),--($D$39:$D$148="P"),$O$39:$O$148),"")) | U37: =IF(COUNTIFS($A$39:$A$148,"Activity",$D$39:$D$148,"P",U$39:U$148,"<>")=0,"",IFERROR(SUMPRODUCT(--($A$39:$A$148="Activity"),--($D$39:$D$148="P"),$O$39:$O$148,U$39:U$148)/SUMPRODUCT(--($A$39:$A$148="Activity"),--($D$39:$D$148="P"),$O$39:$O$148),"")) | V37: =IF(COUNTIFS($A$39:$A$148,"Activity",$D$39:$D$148,"P",V$39:V$148,"<>")=0,"",IFERROR(SUMPRODUCT(--($A$39:$A$148="Activity"),--($D$39:$D$148="P"),$O$39:$O$148,V$39:V$148)/SUMPRODUCT(--($A$39:$A$148="Activity"),--($D$39:$D$148="P"),$O$39:$O$148),"")) | W37: =IF(COUNTIFS($A$39:$A$148,"Activity",$D$39:$D$148,"P",W$39:W$148,"<>")=0,"",IFERROR(SUMPRODUCT(--($A$39:$A$148="Activity"),--($D$39:$D$148="P"),$O$39:$O$148,W$39:W$148)/SUMPRODUCT(--($A$39:$A$148="Activity"),--($D$39:$D$148="P"),$O$39:$O$148),"")) | X37: =IF(COUNTIFS($A$39:$A$148,"Activity",$D$39:$D$148,"P",X$39:X$148,"<>")=0,"",IFERROR(SUMPRODUCT(--($A$39:$A$148="Activity"),--($D$39:$D$148="P"),$O$39:$O$148,X$39:X$148)/SUMPRODUCT(--($A$39:$A$148="Activity"),--($D$39:$D$148="P"),$O$39:$O$148),"")) | Y37: =IF(COUNTIFS($A$39:$A$148,"Activity",$D$39:$D$148,"P",Y$39:Y$148,"<>")=0,"",IFERROR(SUMPRODUCT(--($A$39:$A$148="Activity"),--($D$39:$D$148="P"),$O$39:$O$148,Y$39:Y$148)/SUMPRODUCT(--($A$39:$A$148="Activity"),--($D$39:$D$148="P"),$O$39:$O$148),"")) | ... CO37: =IF(COUNTIFS($A$39:$A$148,"Activity",$D$39:$D$148,"P",CO$39:CO$148,"<>")=0,"",IFERROR(SUMPRODUCT(--($A$39:$A$148="Activity"),--($D$39:$D$148="P"),$O$39:$O$148,CO$39:CO$148)/SUMPRODUCT(--($A$39:$A$148="Activity"),--($D$39:$D$148="P"),$O$39:$O$148),""))
D38: A | M38: =IF(COUNT(R38:CO38)=0,"",SUM(R38:CO38)) | O38: =O37 -> 4300000 | R38: =IF(COUNTIFS($E$39:$E$148,"<>",$D$39:$D$148,"A",R$39:R$148,"<>")=0,"",IFERROR(SUMPRODUCT(--($E$39:$E$148<>""),--($D$39:$D$148="A"),$O$39:$O$148,R$39:R$148)/SUMPRODUCT(--($E$39:$E$148<>""),--($D$39:$D$148="A"),$O$39:$O$148),"")) | S38: =IF(COUNTIFS($E$39:$E$148,"<>",$D$39:$D$148,"A",S$39:S$148,"<>")=0,"",IFERROR(SUMPRODUCT(--($E$39:$E$148<>""),--($D$39:$D$148="A"),$O$39:$O$148,S$39:S$148)/SUMPRODUCT(--($E$39:$E$148<>""),--($D$39:$D$148="A"),$O$39:$O$148),"")) | T38: =IF(COUNTIFS($E$39:$E$148,"<>",$D$39:$D$148,"A",T$39:T$148,"<>")=0,"",IFERROR(SUMPRODUCT(--($E$39:$E$148<>""),--($D$39:$D$148="A"),$O$39:$O$148,T$39:T$148)/SUMPRODUCT(--($E$39:$E$148<>""),--($D$39:$D$148="A"),$O$39:$O$148),"")) | U38: =IF(COUNTIFS($E$39:$E$148,"<>",$D$39:$D$148,"A",U$39:U$148,"<>")=0,"",IFERROR(SUMPRODUCT(--($E$39:$E$148<>""),--($D$39:$D$148="A"),$O$39:$O$148,U$39:U$148)/SUMPRODUCT(--($E$39:$E$148<>""),--($D$39:$D$148="A"),$O$39:$O$148),"")) | V38: =IF(COUNTIFS($E$39:$E$148,"<>",$D$39:$D$148,"A",V$39:V$148,"<>")=0,"",IFERROR(SUMPRODUCT(--($E$39:$E$148<>""),--($D$39:$D$148="A"),$O$39:$O$148,V$39:V$148)/SUMPRODUCT(--($E$39:$E$148<>""),--($D$39:$D$148="A"),$O$39:$O$148),"")) | W38: =IF(COUNTIFS($E$39:$E$148,"<>",$D$39:$D$148,"A",W$39:W$148,"<>")=0,"",IFERROR(SUMPRODUCT(--($E$39:$E$148<>""),--($D$39:$D$148="A"),$O$39:$O$148,W$39:W$148)/SUMPRODUCT(--($E$39:$E$148<>""),--($D$39:$D$148="A"),$O$39:$O$148),"")) | X38: =IF(COUNTIFS($E$39:$E$148,"<>",$D$39:$D$148,"A",X$39:X$148,"<>")=0,"",IFERROR(SUMPRODUCT(--($E$39:$E$148<>""),--($D$39:$D$148="A"),$O$39:$O$148,X$39:X$148)/SUMPRODUCT(--($E$39:$E$148<>""),--($D$39:$D$148="A"),$O$39:$O$148),"")) | Y38: =IF(COUNTIFS($E$39:$E$148,"<>",$D$39:$D$148,"A",Y$39:Y$148,"<>")=0,"",IFERROR(SUMPRODUCT(--($E$39:$E$148<>""),--($D$39:$D$148="A"),$O$39:$O$148,Y$39:Y$148)/SUMPRODUCT(--($E$39:$E$148<>""),--($D$39:$D$148="A"),$O$39:$O$148),"")) | ... CO38: =IF(COUNTIFS($E$39:$E$148,"<>",$D$39:$D$148,"A",CO$39:CO$148,"<>")=0,"",IFERROR(SUMPRODUCT(--($E$39:$E$148<>""),--($D$39:$D$148="A"),$O$39:$O$148,CO$39:CO$148)/SUMPRODUCT(--($E$39:$E$148<>""),--($D$39:$D$148="A"),$O$39:$O$148),""))
A39: WBS | B39: 2.1 | C39: Pilling Work | D39: P | F39: 17 | G39: 17 | H39: 2 | I39: 46230.333 | J39: 46255.667 | M39: =IF(COUNT(R39:CO39)=0,"",SUM(R39:CO39)) -> 1 | O39: =SUMIFS($O$40:$O$41,$A$40:$A$41,"Activity",$D$40:$D$41,"P") -> 100000 | R39: =IF(COUNTIFS($A$41:$A$42,"Activity",$D$41:$D$42,"P",R$41:R$42,"<>")=0,"",IFERROR(SUMPRODUCT(--($A$41:$A$42="Activity"),--($D$41:$D$42="P"),$O$41:$O$42,R$41:R$42)/SUMPRODUCT(--($A$41:$A$42="Activity"),--($D$41:$D$42="P"),$O$41:$O$42),"")) | S39: =IF(COUNTIFS($A$41:$A$42,"Activity",$D$41:$D$42,"P",S$41:S$42,"<>")=0,"",IFERROR(SUMPRODUCT(--($A$41:$A$42="Activity"),--($D$41:$D$42="P"),$O$41:$O$42,S$41:S$42)/SUMPRODUCT(--($A$41:$A$42="Activity"),--($D$41:$D$42="P"),$O$41:$O$42),"")) | T39: =IF(COUNTIFS($A$41:$A$42,"Activity",$D$41:$D$42,"P",T$41:T$42,"<>")=0,"",IFERROR(SUMPRODUCT(--($A$41:$A$42="Activity"),--($D$41:$D$42="P"),$O$41:$O$42,T$41:T$42)/SUMPRODUCT(--($A$41:$A$42="Activity"),--($D$41:$D$42="P"),$O$41:$O$42),"")) | U39: =IF(COUNTIFS($A$41:$A$42,"Activity",$D$41:$D$42,"P",U$41:U$42,"<>")=0,"",IFERROR(SUMPRODUCT(--($A$41:$A$42="Activity"),--($D$41:$D$42="P"),$O$41:$O$42,U$41:U$42)/SUMPRODUCT(--($A$41:$A$42="Activity"),--($D$41:$D$42="P"),$O$41:$O$42),"")) | V39: =IF(COUNTIFS($A$41:$A$42,"Activity",$D$41:$D$42,"P",V$41:V$42,"<>")=0,"",IFERROR(SUMPRODUCT(--($A$41:$A$42="Activity"),--($D$41:$D$42="P"),$O$41:$O$42,V$41:V$42)/SUMPRODUCT(--($A$41:$A$42="Activity"),--($D$41:$D$42="P"),$O$41:$O$42),"")) | W39: =IF(COUNTIFS($A$41:$A$42,"Activity",$D$41:$D$42,"P",W$41:W$42,"<>")=0,"",IFERROR(SUMPRODUCT(--($A$41:$A$42="Activity"),--($D$41:$D$42="P"),$O$41:$O$42,W$41:W$42)/SUMPRODUCT(--($A$41:$A$42="Activity"),--($D$41:$D$42="P"),$O$41:$O$42),"")) | X39: =IF(COUNTIFS($A$41:$A$42,"Activity",$D$41:$D$42,"P",X$41:X$42,"<>")=0,"",IFERROR(SUMPRODUCT(--($A$41:$A$42="Activity"),--($D$41:$D$42="P"),$O$41:$O$42,X$41:X$42)/SUMPRODUCT(--($A$41:$A$42="Activity"),--($D$41:$D$42="P"),$O$41:$O$42),"")) | Y39: =IF(COUNTIFS($A$41:$A$42,"Activity",$D$41:$D$42,"P",Y$41:Y$42,"<>")=0,"",IFERROR(SUMPRODUCT(--($A$41:$A$42="Activity"),--($D$41:$D$42="P"),$O$41:$O$42,Y$41:Y$42)/SUMPRODUCT(--($A$41:$A$42="Activity"),--($D$41:$D$42="P"),$O$41:$O$42),"")) | ... CO39: =IF(COUNTIFS($A$41:$A$42,"Activity",$D$41:$D$42,"P",CO$41:CO$42,"<>")=0,"",IFERROR(SUMPRODUCT(--($A$41:$A$42="Activity"),--($D$41:$D$42="P"),$O$41:$O$42,CO$41:CO$42)/SUMPRODUCT(--($A$41:$A$42="Activity"),--($D$41:$D$42="P"),$O$41:$O$42),""))
D40: A | M40: =IF(COUNT(R40:CO40)=0,"",SUM(R40:CO40)) | O40: =O39 -> 100000 | R40: =IF(COUNTIFS($E$41:$E$42,"<>",$D$41:$D$42,"A",R$41:R$42,"<>")=0,"",IFERROR(SUMPRODUCT(--($E$41:$E$42<>""),--($D$41:$D$42="A"),$O$41:$O$42,R$41:R$42)/SUMPRODUCT(--($E$41:$E$42<>""),--($D$41:$D$42="A"),$O$41:$O$42),"")) | S40: =IF(COUNTIFS($E$41:$E$42,"<>",$D$41:$D$42,"A",S$41:S$42,"<>")=0,"",IFERROR(SUMPRODUCT(--($E$41:$E$42<>""),--($D$41:$D$42="A"),$O$41:$O$42,S$41:S$42)/SUMPRODUCT(--($E$41:$E$42<>""),--($D$41:$D$42="A"),$O$41:$O$42),"")) | T40: =IF(COUNTIFS($E$41:$E$42,"<>",$D$41:$D$42,"A",T$41:T$42,"<>")=0,"",IFERROR(SUMPRODUCT(--($E$41:$E$42<>""),--($D$41:$D$42="A"),$O$41:$O$42,T$41:T$42)/SUMPRODUCT(--($E$41:$E$42<>""),--($D$41:$D$42="A"),$O$41:$O$42),"")) | U40: =IF(COUNTIFS($E$41:$E$42,"<>",$D$41:$D$42,"A",U$41:U$42,"<>")=0,"",IFERROR(SUMPRODUCT(--($E$41:$E$42<>""),--($D$41:$D$42="A"),$O$41:$O$42,U$41:U$42)/SUMPRODUCT(--($E$41:$E$42<>""),--($D$41:$D$42="A"),$O$41:$O$42),"")) | V40: =IF(COUNTIFS($E$41:$E$42,"<>",$D$41:$D$42,"A",V$41:V$42,"<>")=0,"",IFERROR(SUMPRODUCT(--($E$41:$E$42<>""),--($D$41:$D$42="A"),$O$41:$O$42,V$41:V$42)/SUMPRODUCT(--($E$41:$E$42<>""),--($D$41:$D$42="A"),$O$41:$O$42),"")) | W40: =IF(COUNTIFS($E$41:$E$42,"<>",$D$41:$D$42,"A",W$41:W$42,"<>")=0,"",IFERROR(SUMPRODUCT(--($E$41:$E$42<>""),--($D$41:$D$42="A"),$O$41:$O$42,W$41:W$42)/SUMPRODUCT(--($E$41:$E$42<>""),--($D$41:$D$42="A"),$O$41:$O$42),"")) | X40: =IF(COUNTIFS($E$41:$E$42,"<>",$D$41:$D$42,"A",X$41:X$42,"<>")=0,"",IFERROR(SUMPRODUCT(--($E$41:$E$42<>""),--($D$41:$D$42="A"),$O$41:$O$42,X$41:X$42)/SUMPRODUCT(--($E$41:$E$42<>""),--($D$41:$D$42="A"),$O$41:$O$42),"")) | Y40: =IF(COUNTIFS($E$41:$E$42,"<>",$D$41:$D$42,"A",Y$41:Y$42,"<>")=0,"",IFERROR(SUMPRODUCT(--($E$41:$E$42<>""),--($D$41:$D$42="A"),$O$41:$O$42,Y$41:Y$42)/SUMPRODUCT(--($E$41:$E$42<>""),--($D$41:$D$42="A"),$O$41:$O$42),"")) | ... CO40: =IF(COUNTIFS($E$41:$E$42,"<>",$D$41:$D$42,"A",CO$41:CO$42,"<>")=0,"",IFERROR(SUMPRODUCT(--($E$41:$E$42<>""),--($D$41:$D$42="A"),$O$41:$O$42,CO$41:CO$42)/SUMPRODUCT(--($E$41:$E$42<>""),--($D$41:$D$42="A"),$O$41:$O$42),""))
...

Sheet Info
A1: Project | B1: NKC2
A2: Source | B2: C:\Users\Suzanoo\Dev\progress-studio\example\example.xml
A3: WBS / Summary Rows | B3: 82
A4: Activity Rows | B4: 172
A6: Plan Distribution Mode | B6: AUTO
A7: Distribution Report | B7: See sheet: Distribution Report
A8: Auto Default Applied | B8: 133
A10: Interactive Export | B10: READY
A11: OKD Sheets | B11: progress, progress_table
A12: OKD Activities | B12: 172
A13: OKD Weeks | B13: 76
A14: Value Scale | B14: Formula result 0-100 (not Excel %)
A15: OKD WBS Rollup | B15: Included
A16: Calculation | B16: Live formulas linked to main
A17: WBS Rows | B17: Plan and Actual created for every WBS/activity
A18: OKD Child Codes | B18: Generated under parent WBS

Sheet Timescale Info
A1: Setting | B1: Value
A2: Cutoff Day | B2: Friday
A3: Margin Before | B3: 4 Weeks
A4: Margin After | B4: 4 Weeks
A5: Earliest Plan Start | B5: 46076
A6: Latest Plan Finish | B6: 46538
A7: First Week | B7: 46045
A8: Last Week | B8: 46570
A9: Total Weeks | B9: 76
A10: Project Summary | B10: NKC2
A11: Header Levels | B11: Year / Month / Week / Date
A12: Amount Input Option 1 | B12: Enter Amount directly in the main worksheet and skip Script 04.
A13: Amount Input Option 2 | B13: Enter Amount in Amount Mapping and run Script 04.
A14: Mapping Activities | B14: 172

Sheet Amount Mapping
A1: Activity ID | B1: WBS | C1: Description | D1: Amount | E1: Status
C2: NKC2 | E2: Waiting
B3: 1 | C3: งานเตรียมงาน | E3: Waiting
B4: 1.1 | C4: Mobilization | E4: Waiting
A5: A1000 | B5: 1.1.1 | C5: Site Mobilization | D5: 100000 | E5: Mapped
B6: 1.2 | C6: งานรื้อถอน | E6: Waiting
A7: A1005 | B7: 1.2.1 | C7: Roof & Roof Floor | D7: 100000 | E7: Mapped
A8: A1010 | B8: 1.2.2 | C8: 3rd Floor | D8: 100000 | E8: Mapped
A9: A1020 | B9: 1.2.3 | C9: 2nd Floor | D9: 100000 | E9: Mapped
A10: A1030 | B10: 1.2.4 | C10: Mezzanine Floor | D10: 100000 | E10: Mapped
A11: A1040 | B11: 1.2.5 | C11: Ground Floor | D11: 100000 | E11: Mapped
A12: A1050 | B12: 1.2.6 | C12: External | D12: 100000 | E12: Mapped
B13: 1.3 | C13: งานซ่อมโครงสร้าง | E13: Waiting
A14: A1060 | B14: 1.3.1 | C14: Ground FL | D14: 100000 | E14: Mapped
A15: A1070 | B15: 1.3.2 | C15: 2nd FL | D15: 100000 | E15: Mapped
A16: A1080 | B16: 1.3.3 | C16: 3rd FL | D16: 100000 | E16: Mapped
A17: A1090 | B17: 1.3.4 | C17: Roof FL | D17: 100000 | E17: Mapped
B18: 2 | C18: Structure | E18: Waiting
B19: 2.1 | C19: Pilling Work | E19: Waiting
A20: A1100 | B20: 2.1.1 | C20: Bored Pile | D20: 100000 | E20: Mapped
B21: 2.2 | C21: Toilet & Pantry | E21: Waiting
A22: A1110 | B22: 2.2.1 | C22: Foundation | D22: 100000 | E22: Mapped
A23: A1120 | B23: 2.2.2 | C23: RC Beam & Slab for GL.Floor | D23: 100000 | E23: Mapped
A24: A1130 | B24: 2.2.3 | C24: Steel Column & Beam M to R | D24: 100000 | E24: Mapped
A25: A1140 | B25: 2.2.4 | C25: RC Slab M to R | D25: 100000 | E25: Mapped
B26: 2.3 | C26: Lift | E26: Waiting
A27: A1150 | B27: 2.3.1 | C27: Foundation | D27: 100000 | E27: Mapped
A28: A1160 | B28: 2.3.2 | C28: RC Beam & Slab for GL.Floor | D28: 100000 | E28: Mapped
A29: A1170 | B29: 2.3.3 | C29: Steel Column & Beam M to R | D29: 100000 | E29: Mapped
A30: A1180 | B30: 2.3.4 | C30: RC Slab M to R | D30: 100000 | E30: Mapped
B31: 2.4 | C31: Roof Str. | E31: Waiting
A32: A1190 | B32: 2.4.1 | C32: Supports Installation | D32: 100000 | E32: Mapped
A33: A1200 | B33: 2.4.2 | C33: Rafter Truss | D33: 100000 | E33: Mapped
A34: A1210 | B34: 2.4.3 | C34: Purin | D34: 100000 | E34: Mapped
A35: A1220 | B35: 2.4.4 | C35: Paint | D35: 100000 | E35: Mapped
B36: 2.5 | C36: ห้องศาสนา | E36: Waiting
A37: A1230 | B37: 2.5.1 | C37: Supports Installation | D37: 100000 | E37: Mapped
A38: A1240 | B38: 2.5.2 | C38: Steel Columns | D38: 100000 | E38: Mapped
A39: A1250 | B39: 2.5.3 | C39: Steel Roof Frame | D39: 100000 | E39: Mapped
B40: 2.6 | C40: ห้องสนามหลวง | E40: Waiting
...

Sheet Distribution Report
A1: PLAN DISTRIBUTION REPORT
A3: Mode | B3: AUTO | D3: Flat Rate | E3: 133 | G3: Matched Rules | H3: 39
A4: Activities | B4: 172 | D4: Front Loaded | E4: 8 | G4: Default Applied | H4: 133
D5: Back Loaded | E5: 1
D6: Bell Curve | E6: 30
A7: Activity ID | B7: Activity Name | C7: WBS | D7: Plan Start | E7: Plan Finish | F7: Distribution | G7: Source | H7: Matched Rule | I7: Reason
A8: A1000 | B8: Site Mobilization | C8: 1.1.1 | D8: 46076 | E8: 46136 | F8: Front Loaded | G8: Activity Name | H8: mobiliz | I8: Early-production work identified from activity name
A9: A1005 | B9: Roof & Roof Floor | C9: 1.2.1 | D9: 46150 | E9: 46170 | F9: Flat Rate | G9: Default | I9: No matching rule; default distribution applied
A10: A1010 | B10: 3rd Floor | C10: 1.2.2 | D10: 46129 | E10: 46149 | F10: Flat Rate | G10: Default | I10: No matching rule; default distribution applied
A11: A1020 | B11: 2nd Floor | C11: 1.2.3 | D11: 46150 | E11: 46170 | F11: Flat Rate | G11: Default | I11: No matching rule; default distribution applied
A12: A1030 | B12: Mezzanine Floor | C12: 1.2.4 | D12: 46171 | E12: 46191 | F12: Flat Rate | G12: Default | I12: No matching rule; default distribution applied
A13: A1040 | B13: Ground Floor | C13: 1.2.5 | D13: 46192 | E13: 46219 | F13: Flat Rate | G13: Default | I13: No matching rule; default distribution applied
A14: A1050 | B14: External | C14: 1.2.6 | D14: 46220 | E14: 46247 | F14: Flat Rate | G14: Default | I14: No matching rule; default distribution applied
A15: A1060 | B15: Ground FL | C15: 1.3.1 | D15: 46220 | E15: 46233 | F15: Flat Rate | G15: Default | I15: No matching rule; default distribution applied
A16: A1070 | B16: 2nd FL | C16: 1.3.2 | D16: 46234 | E16: 46247 | F16: Flat Rate | G16: Default | I16: No matching rule; default distribution applied
A17: A1080 | B17: 3rd FL | C17: 1.3.3 | D17: 46248 | E17: 46261 | F17: Flat Rate | G17: Default | I17: No matching rule; default distribution applied
A18: A1090 | B18: Roof FL | C18: 1.3.4 | D18: 46262 | E18: 46268 | F18: Flat Rate | G18: Default | I18: No matching rule; default distribution applied
A19: A1100 | B19: Bored Pile | C19: 2.1.1 | D19: 46230 | E19: 46255 | F19: Front Loaded | G19: Activity Name | H19: pile | I19: Early-production work identified from activity name
A20: A1110 | B20: Foundation | C20: 2.2.1 | D20: 46258 | E20: 46276 | F20: Front Loaded | G20: Activity Name | H20: foundation | I20: Early-production work identified from activity name
A21: A1120 | B21: RC Beam & Slab for GL.Floor | C21: 2.2.2 | D21: 46279 | E21: 46290 | F21: Bell Curve | G21: Activity Name | H21: slab | I21: Production work identified from activity name
A22: A1130 | B22: Steel Column & Beam M to R | C22: 2.2.3 | D22: 46293 | E22: 46311 | F22: Bell Curve | G22: Activity Name | H22: beam | I22: Production work identified from activity name
A23: A1140 | B23: RC Slab M to R | C23: 2.2.4 | D23: 46314 | E23: 46332 | F23: Bell Curve | G23: Activity Name | H23: slab | I23: Production work identified from activity name
A24: A1150 | B24: Foundation | C24: 2.3.1 | D24: 46279 | E24: 46287 | F24: Front Loaded | G24: Activity Name | H24: foundation | I24: Early-production work identified from activity name
A25: A1160 | B25: RC Beam & Slab for GL.Floor | C25: 2.3.2 | D25: 46288 | E25: 46296 | F25: Bell Curve | G25: Activity Name | H25: slab | I25: Production work identified from activity name
A26: A1170 | B26: Steel Column & Beam M to R | C26: 2.3.3 | D26: 46297 | E26: 46310 | F26: Bell Curve | G26: Activity Name | H26: beam | I26: Production work identified from activity name
A27: A1180 | B27: RC Slab M to R | C27: 2.3.4 | D27: 46311 | E27: 46324 | F27: Bell Curve | G27: Activity Name | H27: slab | I27: Production work identified from activity name
A28: A1190 | B28: Supports Installation | C28: 2.4.1 | D28: 46251 | E28: 46259 | F28: Bell Curve | G28: Activity Name | H28: installation | I28: Production work identified from activity name
A29: A1200 | B29: Rafter Truss | C29: 2.4.2 | D29: 46260 | E29: 46302 | F29: Flat Rate | G29: Default | I29: No matching rule; default distribution applied
A30: A1210 | B30: Purin | C30: 2.4.3 | D30: 46303 | E30: 46323 | F30: Flat Rate | G30: Default | I30: No matching rule; default distribution applied
A31: A1220 | B31: Paint | C31: 2.4.4 | D31: 46324 | E31: 46332 | F31: Flat Rate | G31: Default | I31: No matching rule; default distribution applied
A32: A1230 | B32: Supports Installation | C32: 2.5.1 | D32: 46303 | E32: 46309 | F32: Bell Curve | G32: Activity Name | H32: installation | I32: Production work identified from activity name
A33: A1240 | B33: Steel Columns | C33: 2.5.2 | D33: 46310 | E33: 46316 | F33: Bell Curve | G33: Activity Name | H33: column | I33: Production work identified from activity name
A34: A1250 | B34: Steel Roof Frame | C34: 2.5.3 | D34: 46317 | E34: 46330 | F34: Flat Rate | G34: Default | I34: No matching rule; default distribution applied
A35: A1260 | B35: Supports Installation | C35: 2.6.1 | D35: 46331 | E35: 46337 | F35: Bell Curve | G35: Activity Name | H35: installation | I35: Production work identified from activity name
A36: A1270 | B36: Steel Columns | C36: 2.6.2 | D36: 46338 | E36: 46344 | F36: Bell Curve | G36: Activity Name | H36: column | I36: Production work identified from activity name
A37: A1280 | B37: Steel Roof Frame | C37: 2.6.3 | D37: 46345 | E37: 46358 | F37: Flat Rate | G37: Default | I37: No matching rule; default distribution applied
A38: A1290 | B38: Supports Installation | C38: 2.7.1 | D38: 46359 | E38: 46365 | F38: Bell Curve | G38: Activity Name | H38: installation | I38: Production work identified from activity name
A39: A1300 | B39: Built-up Frame&Slab | C39: 2.7.2 | D39: 46366 | E39: 46379 | F39: Bell Curve | G39: Activity Name | H39: slab | I39: Production work identified from activity name
A40: A1310 | B40: Concrete Top | C40: 2.7.3 | D40: 46380 | E40: 46386 | F40: Bell Curve | G40: Activity Name | H40: concrete | I40: Production work identified from activity name
A41: A1320 | B41: Supports Installation | C41: 2.8.1 | D41: 46303 | E41: 46309 | F41: Bell Curve | G41: Activity Name | H41: installation | I41: Production work identified from activity name
...

Sheet progress
A1: project_start | B1: project_finish | C1: week_start | D1: plan | E1: actual
A2: =main!I5 -> 46076 | B2: =main!J5 -> 46538 | C2: =main!R4 -> 46045 | D2: =IF(main!R517="","",ROUND(main!R517*100,6)) | E2: =IF(main!R519="","",ROUND(main!R519*100,6))
A3: =main!I5 -> 46076 | B3: =main!J5 -> 46538 | C3: =main!S4 -> 46052 | D3: =IF(main!S517="","",ROUND(main!S517*100,6)) | E3: =IF(main!S519="","",ROUND(main!S519*100,6))
A4: =main!I5 -> 46076 | B4: =main!J5 -> 46538 | C4: =main!T4 -> 46059 | D4: =IF(main!T517="","",ROUND(main!T517*100,6)) | E4: =IF(main!T519="","",ROUND(main!T519*100,6))
A5: =main!I5 -> 46076 | B5: =main!J5 -> 46538 | C5: =main!U4 -> 46066 | D5: =IF(main!U517="","",ROUND(main!U517*100,6)) | E5: =IF(main!U519="","",ROUND(main!U519*100,6))
A6: =main!I5 -> 46076 | B6: =main!J5 -> 46538 | C6: =main!V4 -> 46073 | D6: =IF(main!V517="","",ROUND(main!V517*100,6)) | E6: =IF(main!V519="","",ROUND(main!V519*100,6))
A7: =main!I5 -> 46076 | B7: =main!J5 -> 46538 | C7: =main!W4 -> 46080 | D7: =IF(main!W517="","",ROUND(main!W517*100,6)) -> 0.08809 | E7: =IF(main!W519="","",ROUND(main!W519*100,6))
A8: =main!I5 -> 46076 | B8: =main!J5 -> 46538 | C8: =main!X4 -> 46087 | D8: =IF(main!X517="","",ROUND(main!X517*100,6)) -> 0.197714 | E8: =IF(main!X519="","",ROUND(main!X519*100,6))
A9: =main!I5 -> 46076 | B9: =main!J5 -> 46538 | C9: =main!Y4 -> 46094 | D9: =IF(main!Y517="","",ROUND(main!Y517*100,6)) -> 0.293634 | E9: =IF(main!Y519="","",ROUND(main!Y519*100,6))
A10: =main!I5 -> 46076 | B10: =main!J5 -> 46538 | C10: =main!Z4 -> 46101 | D10: =IF(main!Z517="","",ROUND(main!Z517*100,6)) -> 0.375852 | E10: =IF(main!Z519="","",ROUND(main!Z519*100,6))
A11: =main!I5 -> 46076 | B11: =main!J5 -> 46538 | C11: =main!AA4 -> 46108 | D11: =IF(main!AA517="","",ROUND(main!AA517*100,6)) -> 0.444366 | E11: =IF(main!AA519="","",ROUND(main!AA519*100,6))
A12: =main!I5 -> 46076 | B12: =main!J5 -> 46538 | C12: =main!AB4 -> 46115 | D12: =IF(main!AB517="","",ROUND(main!AB517*100,6)) -> 0.499178 | E12: =IF(main!AB519="","",ROUND(main!AB519*100,6))
A13: =main!I5 -> 46076 | B13: =main!J5 -> 46538 | C13: =main!AC4 -> 46122 | D13: =IF(main!AC517="","",ROUND(main!AC517*100,6)) -> 0.540287 | E13: =IF(main!AC519="","",ROUND(main!AC519*100,6))
A14: =main!I5 -> 46076 | B14: =main!J5 -> 46538 | C14: =main!AD4 -> 46129 | D14: =IF(main!AD517="","",ROUND(main!AD517*100,6)) -> 0.595378 | E14: =IF(main!AD519="","",ROUND(main!AD519*100,6))
A15: =main!I5 -> 46076 | B15: =main!J5 -> 46538 | C15: =main!AE4 -> 46136 | D15: =IF(main!AE517="","",ROUND(main!AE517*100,6)) -> 0.802879 | E15: =IF(main!AE519="","",ROUND(main!AE519*100,6))
A16: =main!I5 -> 46076 | B16: =main!J5 -> 46538 | C16: =main!AF4 -> 46143 | D16: =IF(main!AF517="","",ROUND(main!AF517*100,6)) -> 0.996678 | E16: =IF(main!AF519="","",ROUND(main!AF519*100,6))
A17: =main!I5 -> 46076 | B17: =main!J5 -> 46538 | C17: =main!AG4 -> 46150 | D17: =IF(main!AG517="","",ROUND(main!AG517*100,6)) -> 1.218162 | E17: =IF(main!AG519="","",ROUND(main!AG519*100,6))
A18: =main!I5 -> 46076 | B18: =main!J5 -> 46538 | C18: =main!AH4 -> 46157 | D18: =IF(main!AH517="","",ROUND(main!AH517*100,6)) -> 1.605759 | E18: =IF(main!AH519="","",ROUND(main!AH519*100,6))
A19: =main!I5 -> 46076 | B19: =main!J5 -> 46538 | C19: =main!AI4 -> 46164 | D19: =IF(main!AI517="","",ROUND(main!AI517*100,6)) -> 1.993355 | E19: =IF(main!AI519="","",ROUND(main!AI519*100,6))
A20: =main!I5 -> 46076 | B20: =main!J5 -> 46538 | C20: =main!AJ4 -> 46171 | D20: =IF(main!AJ517="","",ROUND(main!AJ517*100,6)) -> 2.353267 | E20: =IF(main!AJ519="","",ROUND(main!AJ519*100,6))
A21: =main!I5 -> 46076 | B21: =main!J5 -> 46538 | C21: =main!AK4 -> 46178 | D21: =IF(main!AK517="","",ROUND(main!AK517*100,6)) -> 2.547065 | E21: =IF(main!AK519="","",ROUND(main!AK519*100,6))
A22: =main!I5 -> 46076 | B22: =main!J5 -> 46538 | C22: =main!AL4 -> 46185 | D22: =IF(main!AL517="","",ROUND(main!AL517*100,6)) -> 2.740864 | E22: =IF(main!AL519="","",ROUND(main!AL519*100,6))
A23: =main!I5 -> 46076 | B23: =main!J5 -> 46538 | C23: =main!AM4 -> 46192 | D23: =IF(main!AM517="","",ROUND(main!AM517*100,6)) -> 2.927741 | E23: =IF(main!AM519="","",ROUND(main!AM519*100,6))
A24: =main!I5 -> 46076 | B24: =main!J5 -> 46538 | C24: =main!AN4 -> 46199 | D24: =IF(main!AN517="","",ROUND(main!AN517*100,6)) -> 3.07309 | E24: =IF(main!AN519="","",ROUND(main!AN519*100,6))
A25: =main!I5 -> 46076 | B25: =main!J5 -> 46538 | C25: =main!AO4 -> 46206 | D25: =IF(main!AO517="","",ROUND(main!AO517*100,6)) -> 3.218439 | E25: =IF(main!AO519="","",ROUND(main!AO519*100,6))
A26: =main!I5 -> 46076 | B26: =main!J5 -> 46538 | C26: =main!AP4 -> 46213 | D26: =IF(main!AP517="","",ROUND(main!AP517*100,6)) -> 3.363787 | E26: =IF(main!AP519="","",ROUND(main!AP519*100,6))
A27: =main!I5 -> 46076 | B27: =main!J5 -> 46538 | C27: =main!AQ4 -> 46220 | D27: =IF(main!AQ517="","",ROUND(main!AQ517*100,6)) -> 3.550664 | E27: =IF(main!AQ519="","",ROUND(main!AQ519*100,6))
A28: =main!I5 -> 46076 | B28: =main!J5 -> 46538 | C28: =main!AR4 -> 46227 | D28: =IF(main!AR517="","",ROUND(main!AR517*100,6)) -> 3.986711 | E28: =IF(main!AR519="","",ROUND(main!AR519*100,6))
A29: =main!I5 -> 46076 | B29: =main!J5 -> 46538 | C29: =main!AS4 -> 46234 | D29: =IF(main!AS517="","",ROUND(main!AS517*100,6)) -> 4.610304 | E29: =IF(main!AS519="","",ROUND(main!AS519*100,6))
A30: =main!I5 -> 46076 | B30: =main!J5 -> 46538 | C30: =main!AT4 -> 46241 | D30: =IF(main!AT517="","",ROUND(main!AT517*100,6)) -> 5.243275 | E30: =IF(main!AT519="","",ROUND(main!AT519*100,6))
A31: =main!I5 -> 46076 | B31: =main!J5 -> 46538 | C31: =main!AU4 -> 46248 | D31: =IF(main!AU517="","",ROUND(main!AU517*100,6)) -> 5.78984 | E31: =IF(main!AU519="","",ROUND(main!AU519*100,6))
A32: =main!I5 -> 46076 | B32: =main!J5 -> 46538 | C32: =main!AV4 -> 46255 | D32: =IF(main!AV517="","",ROUND(main!AV517*100,6)) -> 6.469177 | E32: =IF(main!AV519="","",ROUND(main!AV519*100,6))
A33: =main!I5 -> 46076 | B33: =main!J5 -> 46538 | C33: =main!AW4 -> 46262 | D33: =IF(main!AW517="","",ROUND(main!AW517*100,6)) -> 7.342611 | E33: =IF(main!AW519="","",ROUND(main!AW519*100,6))
A34: =main!I5 -> 46076 | B34: =main!J5 -> 46538 | C34: =main!AX4 -> 46269 | D34: =IF(main!AX517="","",ROUND(main!AX517*100,6)) -> 8.24475 | E34: =IF(main!AX519="","",ROUND(main!AX519*100,6))
A35: =main!I5 -> 46076 | B35: =main!J5 -> 46538 | C35: =main!AY4 -> 46276 | D35: =IF(main!AY517="","",ROUND(main!AY517*100,6)) -> 8.743143 | E35: =IF(main!AY519="","",ROUND(main!AY519*100,6))
A36: =main!I5 -> 46076 | B36: =main!J5 -> 46538 | C36: =main!AZ4 -> 46283 | D36: =IF(main!AZ517="","",ROUND(main!AZ517*100,6)) -> 9.786017 | E36: =IF(main!AZ519="","",ROUND(main!AZ519*100,6))
A37: =main!I5 -> 46076 | B37: =main!J5 -> 46538 | C37: =main!BA4 -> 46290 | D37: =IF(main!BA517="","",ROUND(main!BA517*100,6)) -> 10.870419 | E37: =IF(main!BA519="","",ROUND(main!BA519*100,6))
A38: =main!I5 -> 46076 | B38: =main!J5 -> 46538 | C38: =main!BB4 -> 46297 | D38: =IF(main!BB517="","",ROUND(main!BB517*100,6)) -> 11.843539 | E38: =IF(main!BB519="","",ROUND(main!BB519*100,6))
A39: =main!I5 -> 46076 | B39: =main!J5 -> 46538 | C39: =main!BC4 -> 46304 | D39: =IF(main!BC517="","",ROUND(main!BC517*100,6)) -> 13.696384 | E39: =IF(main!BC519="","",ROUND(main!BC519*100,6))
A40: =main!I5 -> 46076 | B40: =main!J5 -> 46538 | C40: =main!BD4 -> 46311 | D40: =IF(main!BD517="","",ROUND(main!BD517*100,6)) -> 15.760187 | E40: =IF(main!BD519="","",ROUND(main!BD519*100,6))
...

Sheet progress_table
A1: WBS | B1: Activities | C1: Amount | D1: P/A | E1: %Progress | F1: =main!R4 -> 46045 | G1: =main!S4 -> 46052 | H1: =main!T4 -> 46059 | I1: =main!U4 -> 46066 | J1: =main!V4 -> 46073 | K1: =main!W4 -> 46080 | L1: =main!X4 -> 46087 | M1: =main!Y4 -> 46094 | ... CC1: =main!CO4 -> 46570
A2: PROJECT | B2: =main!C5 -> NKC2 | C2: =main!O5 -> 17200000 | D2: P | E2: =IF(COUNT(F2:CC2)=0,"",ROUND(SUM(F2:CC2),6)) -> 99.999996 | F2: =IF(main!R5="","",ROUND(main!R5*100,6)) | G2: =IF(main!S5="","",ROUND(main!S5*100,6)) | H2: =IF(main!T5="","",ROUND(main!T5*100,6)) | I2: =IF(main!U5="","",ROUND(main!U5*100,6)) | J2: =IF(main!V5="","",ROUND(main!V5*100,6)) | K2: =IF(main!W5="","",ROUND(main!W5*100,6)) -> 0.08809 | L2: =IF(main!X5="","",ROUND(main!X5*100,6)) -> 0.109623 | M2: =IF(main!Y5="","",ROUND(main!Y5*100,6)) -> 0.09592 | ... CC2: =IF(main!CO5="","",ROUND(main!CO5*100,6))
A3: PROJECT | B3: =main!C5 -> NKC2 | C3: =main!O5 -> 17200000 | D3: A | E3: =IF(COUNT(F3:CC3)=0,"",ROUND(SUM(F3:CC3),6)) | F3: =IF(main!R6="","",ROUND(main!R6*100,6)) | G3: =IF(main!S6="","",ROUND(main!S6*100,6)) | H3: =IF(main!T6="","",ROUND(main!T6*100,6)) | I3: =IF(main!U6="","",ROUND(main!U6*100,6)) | J3: =IF(main!V6="","",ROUND(main!V6*100,6)) | K3: =IF(main!W6="","",ROUND(main!W6*100,6)) | L3: =IF(main!X6="","",ROUND(main!X6*100,6)) | M3: =IF(main!Y6="","",ROUND(main!Y6*100,6)) | ... CC3: =IF(main!CO6="","",ROUND(main!CO6*100,6))
A4: 1 | B4: =main!C7 -> งานเตรียมงาน | C4: =main!O7 -> 1100000 | D4: P | E4: =IF(COUNT(F4:CC4)=0,"",ROUND(SUM(F4:CC4),6)) -> 99.999999 | F4: =IF(main!R7="","",ROUND(main!R7*100,6)) | G4: =IF(main!S7="","",ROUND(main!S7*100,6)) | H4: =IF(main!T7="","",ROUND(main!T7*100,6)) | I4: =IF(main!U7="","",ROUND(main!U7*100,6)) | J4: =IF(main!V7="","",ROUND(main!V7*100,6)) | K4: =IF(main!W7="","",ROUND(main!W7*100,6)) -> 1.37741 | L4: =IF(main!X7="","",ROUND(main!X7*100,6)) -> 1.714111 | M4: =IF(main!Y7="","",ROUND(main!Y7*100,6)) -> 1.499847 | ... CC4: =IF(main!CO7="","",ROUND(main!CO7*100,6))
A5: 1 | B5: =main!C7 -> งานเตรียมงาน | C5: =main!O7 -> 1100000 | D5: A | E5: =IF(COUNT(F5:CC5)=0,"",ROUND(SUM(F5:CC5),6)) | F5: =IF(main!R8="","",ROUND(main!R8*100,6)) | G5: =IF(main!S8="","",ROUND(main!S8*100,6)) | H5: =IF(main!T8="","",ROUND(main!T8*100,6)) | I5: =IF(main!U8="","",ROUND(main!U8*100,6)) | J5: =IF(main!V8="","",ROUND(main!V8*100,6)) | K5: =IF(main!W8="","",ROUND(main!W8*100,6)) | L5: =IF(main!X8="","",ROUND(main!X8*100,6)) | M5: =IF(main!Y8="","",ROUND(main!Y8*100,6)) | ... CC5: =IF(main!CO8="","",ROUND(main!CO8*100,6))
A6: 1.1 | B6: =main!C9 -> Mobilization | C6: =main!O9 -> 100000 | D6: P | E6: =IF(COUNT(F6:CC6)=0,"",ROUND(SUM(F6:CC6),6)) -> 99.999999 | F6: =IF(main!R9="","",ROUND(main!R9*100,6)) | G6: =IF(main!S9="","",ROUND(main!S9*100,6)) | H6: =IF(main!T9="","",ROUND(main!T9*100,6)) | I6: =IF(main!U9="","",ROUND(main!U9*100,6)) | J6: =IF(main!V9="","",ROUND(main!V9*100,6)) | K6: =IF(main!W9="","",ROUND(main!W9*100,6)) -> 15.151515 | L6: =IF(main!X9="","",ROUND(main!X9*100,6)) -> 18.855219 | M6: =IF(main!Y9="","",ROUND(main!Y9*100,6)) -> 16.498316 | ... CC6: =IF(main!CO9="","",ROUND(main!CO9*100,6))
A7: 1.1 | B7: =main!C9 -> Mobilization | C7: =main!O9 -> 100000 | D7: A | E7: =IF(COUNT(F7:CC7)=0,"",ROUND(SUM(F7:CC7),6)) | F7: =IF(main!R10="","",ROUND(main!R10*100,6)) | G7: =IF(main!S10="","",ROUND(main!S10*100,6)) | H7: =IF(main!T10="","",ROUND(main!T10*100,6)) | I7: =IF(main!U10="","",ROUND(main!U10*100,6)) | J7: =IF(main!V10="","",ROUND(main!V10*100,6)) | K7: =IF(main!W10="","",ROUND(main!W10*100,6)) | L7: =IF(main!X10="","",ROUND(main!X10*100,6)) | M7: =IF(main!Y10="","",ROUND(main!Y10*100,6)) | ... CC7: =IF(main!CO10="","",ROUND(main!CO10*100,6))
